Workbook

Sheet 🏠 Project Info
B1: OpenCart Platform — Test Case Document
B3: 📁 PROJECT DETAILS
B4: Project Name | C4: OpenCart Platform | D4: Project ID | E4: OC_TC
B5: Module | C5: Authentication | Search | Category Navigation | Product Compare | Wishlist | Shopping Cart | Currency | Registration | Login | D5: Version / Release | E5: 1.0.0
B6: Base URL | C6: https://awesomeqa.com/ui/index.php | D6: Environment | E6: Staging
B7: Total Test Cases | C7: 358 | D7: Priority Levels | E7: P0 / P1 / P2 / P3
B8: Prepared By | C8: Mohamed Ahmed | D8: Date Created | E8: 46124
B9: Reviewed By | D9: Last Updated | E9: 46162
B10: Approved By | D10: Status | E10: Ready for Review
B12: 🖥️ TEST ENVIRONMENT
B13: Browsers | C13: Chrome 120+ | Firefox 120+ | Edge 120+ | Safari 17+ | E13: Windows 11 | macOS | Android | iOS
B14: Screen Sizes | C14: Desktop (1920×1080) | Tablet (768px) | Mobile (375px) | E14: Normal Load
B16: 🎯 SCOPE & OBJECTIVES
B17: Test Objective | C17: Validate all functional, validation, boundary, security, and UI behaviors across the full OpenCart platform modules including Authentication, Search, Category Navigation, Product Compare, Wishlist, Shopping Cart, Currency, and more.
B18: In Scope | C18: Login & Registration | Search (Functional, BVA, EP, Error Handling, UI) | Category Navigation | Product Compare | Wishlist | Shopping Cart | Currency Selector | Breadcrumb Navigation | Responsive UI | Performance | Security (SQL Injection, XSS) | Cross-browser | Mobile responsiveness
B19: Out of Scope | C19: Backend database internals | Third-party integrations | Payment gateway | Admin panel functionality
B20: Entry Criteria | C20: Application deployed on Staging | All modules accessible | Test data prepared | Test environment verified
B21: Exit Criteria | C21: All P0 & P1 test cases executed | No open Blocker/Critical bugs | Test report reviewed and signed off
B23: 🚦 PRIORITY MODEL
B24: Priority Level | C24: Code | D24: # Cases | E24: Definition
B25: P0 – Blocker | C25: P0 | D25: 7 | E25: Prevents core functionality or compromises security/data integrity
B26: P1 – High Risk | C26: P1 | D26: 181 | E26: Critical validation rules ensuring correct and secure behavior across all modules
B27: P2 – Medium Risk | C27: P2 | D27: 121 | E27: Boundary conditions, formatting, and non-critical functional behavior
B28: P3 – Low Risk | C28: P3 | D28: 49 | E28: UI, usability, accessibility, and visual behavior

Sheet 🧪 Test Cases
A1: 🧪 OpenCart Platform — Test Cases
A2: TC ID | B2: Test Case Title | C2: Sub-Module | D2: Priority | E2: Test Type | F2: Pre-conditions | G2: Test Steps | H2: Test Data | I2: Expected Result | J2: Actual Result | K2: Status | L2: Severity | M2: Tested By | N2: Exec Date | O2: Comments / Bug ID
A3: OC_AUTH_TC_001 | B3: Verify Registration Succeeds When All Mandatory Fields Are Valid | C3: Registration – Core Flow | D3: P0 | E3: Functional | F3: Registration page loaded | G3: 1. Navigate to registration URL 2. Fill First Name: John 3. Fill Last Name: Doe 4. Fill Email: john.doe@test.com 5. Fill Telephone: 0501234567 6. Fill Password: Test@1234 7. Confirm Password: Test@1234 8. Accept Privacy Policy 9. Click Continue | H3: First Name: John | Last Name: Doe | Email: john.doe@test.com | Tel: 0501234567 | Password: Test@1234 | PP: Accepted | I3: User registered successfully | Redirected to account page | Welcome message displayed | J3: User is successfully registered after entering all valid mandatory fields. The system redirects the user to the account page, and a welcome message is displayed confirming successful registration. | K3: Pass | L3: Critical | M3: Mohamed Ahmed | N3: 46360 | O3: —
A4: OC_AUTH_TC_002 | B4: Verify Registration Fails When First Name Contains SQL Injection Payload | C4: Registration – Security | D4: P0 | E4: Security | F4: Registration page loaded WAF/Firewall disabled or configured for testing Database logging enabled | G4: 1. Enter SQL injection in First Name: ' OR '1'='1 2. Fill other fields normally with valid data 3. Accept Privacy Policy 4. Click Continue | H4: First Name: ' OR '1'='1 | Others: valid | I4: Registration rejected | No SQL error exposed | Generic validation message shown | Application remains stable | J4: The system allowed registration to be completed despite entering SQL injection payload in the input field. The user account was successfully created, and the application redirected to the account information page. The injected input was stored and displayed as plain text in the user profile (e.g., name field contained ' OR '1'='1) | K4: Fail | L4: Critical | M4: Mohamed Ahmed | N4: 46360 | O4: OC_AUTH_BUG_001
A5: OC_AUTH_TC_003 | B5: Verify Registration Fails When First Name Contains XSS Script Payload | C5: Registration – Security | D5: P0 | E5: Security | F5: Registration page loaded WAF/Firewall disabled or configured for testing Database logging enabled | G5: 1. Enter XSS payload in First Name: <script>alert('XSS')</script> 2. Fill other fields normally 3. Accept Privacy Policy 4. Click Continue | H5: First Name: <script>alert('XSS')</script> | I5: Registration rejected | Script not executed | No alert popup | Input sanitized | No executable code stored | J5: The system prevents registration submission when the First Name field contains XSS script input. A validation error message is displayed indicating that the First Name must be between 1 and 32 characters, and the registration process is blocked. No script execution or alert popup occurs, and the application remains stable. | K5: Pass | L5: Critical | M5: Mohamed Ahmed | N5: 46360 | O5: —
A6: OC_AUTH_TC_004 | B6: Verify Login Succeeds When All Credentials Are Valid | C6: Login – Core Flow | D6: P0 | E6: Functional | F6: Login page loaded User account exists with email: test@domain.com and password: Test123! | G6: 1. Navigate to login URL 2. Enter Email: test@domain.com 3. Enter Password: Test123! 4. Click Login | H6: Email: test@domain.com | Password: Test123! | I6: User logged in successfully | Redirected to My Account page | Dashboard fully rendered | J6: User logged in successfully | The system redirected to the My Account page All dashboard elements loaded and displayed correctly without errors. | K6: Pass | L6: Critical | M6: Mohamed Ahmed | N6: 46360 | O6: —
A7: OC_AUTH_TC_005 | B7: Verify Login Fails When Email Field Contains SQL Injection Payload | C7: Login – Security | D7: P0 | E7: Security | F7: Login page loaded | G7: 1. Enter SQL injection in Email: ' OR '1'='1 2. Enter any Password 3. Click Login | H7: Email: ' OR '1'='1 | Password: Test123! | I7: Login rejected | No SQL error exposed | Generic validation message shown | Application remains stable | J7: Login attempt was rejected. No SQL-related error messages were displayed. A generic validation message was shown to the user. The application remained stable and responsive. | K7: Pass | L7: Critical | M7: Mohamed Ahmed | N7: 46360 | O7: —
A8: OC_AUTH_TC_006 | B8: Verify Login Fails When Email Field Contains XSS Script Payload | C8: Login – Security | D8: P0 | E8: Security | F8: Login page loaded | G8: 1. Enter XSS payload in Email: <script>alert('XSS')</script> 2. Enter any Password 3. Click Login | H8: Email: <script>alert('XSS')</script> | Password: Test123! | I8: Input sanitized or rejected | No script executed | No alert popup | Application remains stable | J8: Login attempt with XSS payload was handled securely.The input was sanitized/rejected successfully. No script was executed, and no alert popup appeared. The application remained stable and responsive without any issues. | K8: Pass | L8: Critical | M8: Mohamed Ahmed | N8: 46360 | O8: —
A9: OC_AUTH_TC_007 | B9: Verify Registration Fails When All Mandatory Fields Are Empty | C9: Registration – Core Flow | D9: P1 | E9: Functional | F9: Registration page loaded | G9: 1. Leave all fields empty 2. Do NOT accept Privacy Policy 3. Click Continue | H9: All fields: empty | Privacy Policy: not accepted | I9: Registration rejected | Warning: "You must agree to the Privacy Policy!" | Validation errors for all required fields | J9: The system prevents registration submission when all mandatory fields are left empty. Validation error messages are displayed for all required fields, and a warning message stating that agreement to the Privacy Policy is required is shown. | K9: Pass | L9: Critical | M9: Mohamed Ahmed | N9: 46360 | O9: —
A10: OC_AUTH_TC_008 | B10: Verify Registration Fails When E-Mail Is Already Registered | C10: Registration – Email | D10: P1 | E10: Functional | F10: Email "existing@test.com" already registered in system | G10: 1. Enter already-registered email: existing@test.com 2. Fill all other fields with valid data 3. Accept Privacy Policy 4. Click Continue | H10: Email: existing@test.com (duplicate) | I10: Registration rejected | Error: "Warning: E-Mail Address is already registered!" | J10: The system prevents registration when an already registered email address is entered. A warning message is displayed indicating that the E-Mail Address is already registered. | K10: Pass | L10: Critical | M10: Mohamed Ahmed | N10: 46360 | O10: —
A11: OC_AUTH_TC_009 | B11: Verify Registration Fails When E-Mail Matches Existing Account In Different Case | C11: Registration – Email | D11: P1 | E11: Functional | F11: Email "user@test.com" already registered in system | G11: 1. Enter email in uppercase: USER@TEST.COM 2. Fill all other fields with valid data 3. Accept Privacy Policy 4. Click Continue | H11: Email: USER@TEST.COM (existing lowercase: user@test.com) | I11: Registration rejected | System treats emails as case-insensitive | Error: "Warning: E-Mail Address is already registered!" | J11: The system prevents registration when an email address that differs only in letter case from an already registered email is entered. The system treats email addresses as case-insensitive and displays a warning message indicating that the E-Mail Address is already registered. | K11: Pass | L11: Critical | M11: Mohamed Ahmed | N11: 46360 | O11: —
A12: OC_AUTH_TC_010 | B12: Verify Registration Fails When Telephone Is Already Registered | C12: Registration – Telephone | D12: P1 | E12: Functional | F12: System has existing account with Telephone: 0501234567 | G12: 1. Enter Telephone: 0501234567 (already registered) 2. Fill other fields with unique valid data 3. Accept Privacy Policy 4. Click Continue | H12: Telephone: 0501234567 (duplicate) | Others: unique valid data | I12: Registration rejected | System prevents duplicate telephone numbers | J12: The system allowed registration to be completed successfully even when the telephone number was already registered. No validation error was displayed, and the account was created using a duplicate telephone value. | K12: Fail | L12: Major | M12: Mohamed Ahmed | N12: 46360 | O12: OC_AUTH_BUG_002
A13: OC_AUTH_TC_011 | B13: Verify Registration Fails When Password And Password Confirm Do Not Match | C13: Registration – Password | D13: P1 | E13: Functional | F13: Registration page loaded | G13: 1. Fill Password: Test@1234 2. Fill Confirm Password: Test@5678 3. Fill other fields with valid data 4. Accept Privacy Policy 5. Click Continue | H13: Password: Test@1234 | Confirm: Test@5678 | I13: Registration rejected | Error: "Password confirmation does not match password!" | J13: The system prevents registration submission when the Password and Confirm Password fields contain mismatched values. A validation error message is displayed indicating that the password confirmation does not match the password. | K13: Pass | L13: Critical | M13: Mohamed Ahmed | N13: 46360 | O13: —
A14: OC_AUTH_TC_012 | B14: Verify Registration Fails When Privacy Policy Is Not Checked | C14: Registration – Privacy Policy | D14: P1 | E14: Functional | F14: Registration page loaded | G14: 1. Fill all mandatory fields with valid data 2. Do NOT check Privacy Policy checkbox 3. Click Continue | H14: All fields: valid | Privacy Policy: unchecked | I14: Registration rejected | Error: "Warning: You must agree to the Privacy Policy!" | J14: The system prevents registration submission when the Privacy Policy checkbox is not selected. A warning message is displayed indicating that the user must agree to the Privacy Policy before proceeding with registration. | K14: Pass | L14: Critical | M14: Mohamed Ahmed | N14: 46360 | O14: —
... A100: OC_AUTH_TC_098 | B100: Verify Login Fails With Old Password After Reset | C100: Login – Recovery | D100: P2 | E100: Functional | F100: User has successfully reset password to: NewPass123! | Old password was: Test123! | G100: 1. Navigate to Login page 2. Enter Email: test@domain.com 3. Enter old Password: Test123! 4. Click Login | H100: Email: test@domain.com | Old Password: Test123! | I100: Login rejected | Warning: "No match for E-Mail Address and/or Password" displayed | J100: Reset link is not generated or sent | Test case cannot be executed as precondition is not met | K100: Blocked | L100: Minor | M100: Mohamed Ahmed | N100: 46360 | O100: Blocked | Depends on OC_AUTH_BUG_017 fix (TC_057)
A101: OC_AUTH_TC_099 | B101: Verify Password Reset Email Can Be Resent Successfully | C101: Login – Recovery | D101: P2 | E101: Functional | F101: Forgotten Password page loaded | G101: 1. Enter valid registered email 2. Click Continue 3. Return to Forgotten Password page 4. Enter the same email again 5. Click Continue | H101: Email: test@domain.com (registered) | I101: New reset email sent successfully | User can request reset email more than once | J101: Password reset email was not sent | System did not deliver any reset email | K101: Fail | L101: Minor | M101: Mohamed Ahmed | N101: 46360 | O101: OC_AUTH_BUG_021 | Q101: د
A102: OC_AUTH_TC_100 | B102: Verify Login Responds Within 3 Seconds Under Normal Load | C102: Login – Performance | D102: P2 | E102: Performance | F102: Valid credentials prepared | Login page loaded | Normal network load | G102: 1. Enter valid Email and Password 2. Start timer 3. Click Login 4. Stop timer when My Account page appears | H102: Email: test@domain.com | Password: Test123! | I102: Login completes successfully | Total response time ≤ 3 seconds | J102: Login completed successfully | Total response time = 1.4s | Response time ≤ 3 seconds threshold met | K102: Pass | L102: Minor | M102: Mohamed Ahmed | N102: 46360 | O102: —
A103: OC_AUTH_TC_101 | B103: Verify Login Displays Connection Error When Network Is Unavailable | C103: Login – Network | D103: P2 | E103: Functional | F103: Valid credentials prepared | Network connection disabled | G103: 1. Disable network connection 2. Enter valid credentials 3. Click Login | H103: Network: unavailable | Email: test@domain.com | Password: Test123! | I103: Appropriate connection error message displayed | Prompt to check internet and retry | J103: Appropriate connection error message displayed | Prompt to check internet and retry | K103: Pass | L103: Minor | M103: Mohamed Ahmed | N103: 46360 | O103: —
A104: OC_AUTH_TC_102 | B104: Verify Login Shows Loading Indicator And Completes On Slow Network (3G) | C104: Login – Performance | D104: P2 | E104: Functional | F104: Valid credentials prepared | Network throttled to 3G speed via browser dev tools | G104: 1. Throttle network to 3G in browser dev tools 2. Enter valid credentials 3. Click Login 4. Observe loading indicator | H104: Network: 3G | Email: test@domain.com | Password: Test123! | I104: Loading indicator displayed during request | Login completes successfully after delay | J104: Loading indicator displayed during request | Login completes successfully after delay | K104: Pass | L104: Minor | M104: Mohamed Ahmed | N104: 46360 | O104: —
A105: OC_AUTH_TC_103 | B105: Verify Logout Terminates Session And Redirects To Confirmation Page | C105: Login – Session | D105: P2 | E105: Functional | F105: User is logged in | G105: 1. Navigate to My Account 2. Click Logout | H105: User: logged in | I105: Session terminated | Redirected to logout confirmation page | Clear success message displayed | J105: Session terminated | Redirected to logout confirmation page | Clear success message displayed | K105: Pass | L105: Minor | M105: Mohamed Ahmed | N105: 46360 | O105: —
A106: OC_AUTH_TC_104 | B106: Verify Clicking Continue After Logout Redirects To Home Page | C106: Login – Navigation | D106: P2 | E106: Functional | F106: User has just logged out and is on the logout confirmation page | G106: 1. Click Continue on the logout confirmation page | H106: User: on logout confirmation page | I106: Redirected to the platform home page | J106: Redirected to the platform home page | K106: Pass | L106: Minor | M106: Mohamed Ahmed | N106: 46360 | O106: —
A107: OC_AUTH_TC_105 | B107: Verify Logout From One Tab Terminates Session In All Other Tabs | C107: Login – Session | D107: P2 | E107: Functional | F107: User is logged in across multiple tabs in the same browser | G107: 1. Open My Account in two or more tabs 2. Log out from one tab 3. Switch to another tab and observe session state | H107: Multiple browser tabs: all logged in | I107: Session terminated in all open tabs | Other tabs redirect to login page | J107: Session terminated in all open tabs | Other tabs redirect to login page | K107: Pass | L107: Minor | M107: Mohamed Ahmed | N107: 46360 | O107: —
A108: OC_AUTH_TC_106 | B108: Verify Logout From One Browser Terminates Session In All Other Browsers | C108: Login – Session | D108: P2 | E108: Functional | F108: User is logged in on multiple browsers simultaneously (e.g., Chrome and Edge) | G108: 1. Log in on Chrome and Edge simultaneously 2. Log out from Chrome 3. Observe session state in Edge | H108: Chrome: logged in | Edge: logged in | I108: Session terminated in both browsers | Edge redirects to login page after logout in Chrome | J108: Session terminated in both browsers | Edge redirects to login page after logout in Chrome | K108: Pass | L108: Minor | M108: Mohamed Ahmed | N108: 46360 | O108: —
A109: OC_AUTH_TC_107 | B109: Verify Registration Succeeds Across All Supported Browsers | C109: Registration – Browser Compat | D109: P3 | E109: Compatibility | F109: Supported browsers installed: Chrome 120+, Edge 120+ | G109: 1. Open registration URL in Chrome 2. Fill all fields with valid data and submit 3 Repeat in Edge 4. Compare UI rendering and form behavior across all browsers | H109: Browser: Chrome / Edge | Valid registration data | I109: All UI elements render correctly | Form validation behaves consistently | Registration succeeds in all browsers | J109: Registration functionality was tested across supported browsers. The registration form rendered correctly in all tested browsers, and all UI elements were displayed as expected. Form validation behavior was consistent across browsers, and user registration was completed successfully without functional discrepancies. | K109: Pass | L109: Minor | M109: Mohamed Ahmed | N109: 46360 | O109: —
A110: OC_AUTH_TC_108 | B110: Verify Validation Error Messages Appear Next To Their Fields | C110: Registration – UI | D110: P3 | E110: UI | F110: Registration page loaded | G110: 1. Submit form with invalid data in multiple fields 2. Observe error message positioning 3. Verify each error appears near its respective field 4. Verify error text contrast and readability | H110: Various invalid inputs submitted simultaneously | I110: Clear and specific error message near each invalid field | No internal logic exposed | Sufficient color contrast | J110: Validation error messages are displayed adjacent to their corresponding input fields when invalid data is entered. The messages are clear, specific, and directly related to the affected fields. No internal system logic or technical details are exposed to the user. | K110: Pass | L110: Low | M110: Mohamed Ahmed | N110: 46360 | O110: —
A111: OC_AUTH_TC_109 | B111: Verify Password Visibility Toggle Works On All Supported Browsers | C111: Registration – UI | D111: P3 | E111: UI | F111: Registration page loaded in Chrome and Edge | G111: 1. Open registration page in Chrome 2. Locate password visibility toggle next to Password field 3. Click toggle — password should become visible 4. Click again — password should be masked 5. Repeat in Edge 6. Verify toggle is custom (not browser-native) | H111: Browser: Chrome | Edge | Custom toggle expected | I111: Custom visibility toggle visible next to Password field | Toggle works correctly in Chrome and Edge | J111: The password visibility toggle is not displayed in Google Chrome. The toggle control is missing next to the Password field, preventing users from enabling or disabling password visibility in this browser. No functional interaction is available for this feature in Chrome. | K111: Fail | L111: Low | M111: Mohamed Ahmed | N111: 46360 | O111: OC_AUTH_BUG_022
A112: OC_AUTH_TC_110 | B112: Verify Tab Key Navigates Registration Fields In Sequential Order | C112: Registration – Usability | D112: P3 | E112: Accessibility | F112: Registration page loaded | Keyboard-only navigation | G112: 1. Place focus on first field (First Name) 2. Press Tab repeatedly 3. Observe focus order through all fields 4. Verify logical sequential order 5. Press Shift+Tab to move backward | H112: Keyboard navigation: Tab | Shift+Tab | I112: Tab moves focus forward logically | Shift+Tab moves backward | No keyboard trap | J112: The Tab key successfully navigates through the registration form fields in a logical sequential order. Shift + Tab correctly moves focus backward through the fields. No keyboard traps were observed, and users can navigate the form using only the keyboard without interruption. | K112: Pass | L112: Low | M112: Mohamed Ahmed | N112: 46360 | O112: —
A113: OC_AUTH_TC_111 | B113: Verify Enter Key Triggers Registration Form Submission | C113: Registration – Usability | D113: P3 | E113: Usability | F113: Registration page loaded | All fields filled with valid data | G113: 1. Fill all mandatory fields with valid data 2. Navigate to Continue button using Tab 3. Press Enter key 4. Observe form submission behavior | H113: Keyboard: Enter on Continue button | All fields: valid | I113: Form submitted when Enter pressed on Continue button | Behavior same as mouse click | J113: The registration form is successfully submitted when the Enter key is pressed while focusing on the form (e.g., input fields or Continue button). The behavior is identical to clicking the Continue button using a mouse, and the registration process is completed successfully. | K113: Pass | L113: Low | M113: Mohamed Ahmed | N113: 46360 | O113: —
... A315: OC_CURR_TC_313 | B315: Verify currency change performance and page response time after selecting different currencies | C315: Performance | D315: P1 | E315: Performance Testing | F315: Website is accessible Products are loaded on Home / Category pages Currency selector is available Stable network connection | G315: 1. Open the website home page 2. Open browser DevTools (Network tab) 3. Measure initial page load time 4. Select a currency (e.g. USD) 5. Measure time taken for prices to update 6. Navigate to category page and repeat currency change 7. Repeat for Cart and Wishlist pages 8. Compare response time across pages | H315: Currencies: EGP / USD / EUR Pages: Home, Category, Cart, Wishlist Network: Normal broadband connection | I315: Currency change is reflected within acceptable response time (e.g. < 2–3 seconds) No noticeable lag when updating product prices Page does not freeze or reload unexpectedly Performance remains consistent across all pages No degradation when switching between currencies multiple times | J315: On first interaction (opening and selecting currency), currency change took approximately 10 ms, which is instant and acceptable. On subsequent currency changes, response time was around 600 ms on mobile. A second currency change took approximately 500 ms on mobile. On desktop view, currency change response time was around 400 ms. No UI freezing or crashes were observed during currency switching. Overall performance is acceptable, but slight variation in response time is observed between first and subsequent interactions and across devices. | K315: Pass | L315: Major | M315: Mariam Elgandour | N315: 46360 | O315: —
A316: OC_CART_TC_314 | B316: Verify successful order placement with valid checkout data | C316: Checkout / Order Placement | D316: P0 | E316: Functional / E2E | F316: Product is added to cart checkout page is opened All required billing details are filled correctly Valid payment method is available | G316: 1.Add product to cart 2.Proceed to checkout page 3.Fill all required billing information with valid data 4.Accept Terms & Conditions 5.Verify available payment method 6.Click on "Confirm Order" button | H316: Product: HTC Touch HD Billing Details: Valid Payment Method: Available valid method | I316: System should place the order successfully and display a confirmation message indicating successful order processing | J316: System successfully places the order and displays the message: "Your order has been placed! Your order has been successfully processed!" | K316: Pass | L316: Critical | M316: Maryam Saleh | N316: 12/04/2026 | O316: —
A317: OC_CART_TC_315 | B317: Verify Adding Single Product to Cart from Home Page | C317: Cart / Home Page | D317: P1 | E317: Functional | F317: User is on Home Page | G317: 1.Open url "https://awesomeqa.com/ui/" 2.Click on "Add to Cart" button for Product | H317: Product : MacBook or iPhone | I317: Product is added successfully to the cart and success message is displayed | J317: Product is added successfully to the cart | K317: Pass | L317: Critical | M317: Maryam Saleh | N317: 12/04/2026 | O317: —
A318: OC_CART_TC_316 | B318: Verify Adding (Apple Cinema 30") to cart after selecting required options | C318: Cart / Product Details | D318: P1 | E318: Functional | F318: User is on Home Page | G318: 1.Open url "https://awesomeqa.com/ui/" 2.Click on (Apple Cinema 30") product 3.Select required options 4.Click on "Add to Cart" button | H318: Product: Apple Cinema 30 Options: Select all mandatory fields (e.g., Radio = option 1, Checkbox = checked, Text = "Test") | I318: Product is added successfully to the cart after selecting all required options and a success message is displayed | J318: Product is added successfully to the cart | K318: Pass | L318: Critical | M318: Maryam Saleh | N318: 12/04/2026 | O318: —
A319: OC_CART_TC_317 | B319: Verify error when adding "Apple Cinema 30" with quantity less than minimum (1) | C319: Cart / Product Details | D319: P1 | E319: Negative | F319: User is on Product Details page | G319: 1.Click on (Apple Cinema 30") product 2.Enter quantity = 1 3.Select required options 4.Click "Add to Cart" | H319: Product: Apple Cinema 30 Quantity: 1 | I319: System should display an error message and prevent adding the product to the cart | J319: Product is added successfully with quantity = 1 | K319: Fail | L319: Critical | M319: Maryam Saleh | N319: 12/04/2026 | O319: OC_CART_BUG_001
A320: OC_CART_TC_318 | B320: Verify that "Apple Cinema 30" does not allow selecting past dates in the date field | C320: Product Details | D320: P1 | E320: Negative | F320: User is on Product Details page | G320: 1.Open "Apple Cinema 30" product page 2.Select a past date 3.Click "Add to Cart" | H320: Product: Apple Cinema 30 Date: Any past date (e.g., 01/01/2020) | I320: System should NOT allow selecting past dates and should display validation error | J320: System allows selecting past dates and proceeds without validation error | K320: Fail | L320: Major | M320: Maryam Saleh | N320: 12/04/2026 | O320: OC_CART_BUG_002
A321: OC_CART_TC_319 | B321: Verify availability of required options for "Canon EOS 5D" product before adding to cart | C321: Product Details | D321: P1 | E321: Functional / Negative | F321: User is on Product Details page | G321: 1.Open "Canon EOS 5D" product 2.Open dropdown/select field 3.Click "Add to Cart" | H321: Product: Canon EOS 5D Dropdown Options: ---Please Select--- Quantity: 1 | I321: Required options should be visible and selectable before adding product to cart | J321: Dropdown/select field is present but no options are available, and system shows "Select required options" message | K321: Fail | L321: Critical | M321: Maryam Saleh | N321: 12/04/2026 | O321: OC_CART_BUG_003
A322: OC_CART_TC_320 | B322: Verify adding "Samsung Galaxy Tab 10.1" pre-order product to cart successfully | C322: Menu Navigation / Product Details / Cart | D322: P1 | E322: Functional | F322: User is on Home Page | G322: 1.Click on "Tablets" from the menu bar 2.Click on "Samsung Galaxy Tab 10.1" 3.Click on "Add to Cart" button | H322: Category: Tablets Product: Samsung Galaxy Tab 10.1 Availability: Pre-Order | I322: Product should be successfully added to the cart and remain marked as Pre-Order (if applicable) | J322: Product is added successfully to the cart | K322: Pass | L322: Critical | M322: Maryam Saleh | N322: 12/04/2026 | O322: —
A323: OC_CART_TC_321 | B323: Verify that "iPhone" (Out of Stock) cannot be added to cart | C323: Menu Navigation / Product Details / Cart | D323: P1 | E323: Functional / Negative | F323: User is on Home Page | G323: 1.Click on "Phones & PDAs" from the menu bar 2.Select "iPhone" 3.Click on "Add to Cart" button | H323: Category: Phones & PDAs Product: iPhone Availability: Out of Stock | I323: System should NOT allow adding the product to the cart and should display an appropriate message | J323: Product is added to the cart but cannot proceed to checkout | K323: Fail | L323: Major | M323: Maryam Saleh | N323: 12/04/2026 | O323: OC_CART_BUG_004
A324: OC_CART_TC_322 | B324: Verify that "HP LP3065" does not allow selecting past dates in Delivery Date field | C324: Menu Navigation / Product Details / Cart | D324: P1 | E324: Functional / Negative | F324: User is on Home Page | G324: 1.Hover over "Desktops" from the menu bar 2.Click on "Show All Desktops" 3.Select "HP LP3065" 4.Locate the "Delivery Date" field 5.Open the date picker 6.Select a past date 7.Click on "Add to Cart" button | H324: Category: Desktops Product: HP LP3065 Delivery Date: Any past date (e.g., 01/01/2020) | I324: System should prevent selecting past dates and display an appropriate validation message | J324: System allows selecting past dates without validation | K324: Fail | L324: Major | M324: Maryam Saleh | N324: 12/04/2026 | O324: OC_CART_BUG_005
A325: OC_CART_TC_323 | B325: Verify error message when adding "HP LP3065" to cart without selecting Delivery Date | C325: Menu Navigation / Product Details / Cart | D325: P1 | E325: Functional / Negative | F325: User is on "HP LP3065" product details page | G325: 1.Hover over "Desktops" from the menu bar 2.Click on "Show All Desktops" 3.Select "HP LP3065" 4.Leave the "Delivery Date" field empty 5.Click on "Add to Cart" button | H325: Category: Desktops Product: HP LP3065 Delivery Date: Empty | I325: System should display "Delivery Date required!" validation message and prevent adding the product to the cart | J325: "Delivery Date required!" message is displayed and product is not added to cart | K325: Pass | L325: Critical | M325: Maryam Saleh | N325: 12/04/2026 | O325: —
A326: OC_CART_TC_324 | B326: Verify adding multiple different products to cart successfully | C326: Cart / Home Page / Product Details | D326: P1 | E326: Functional | F326: User is on Home Page | G326: 1.Navigate to a product category from the menu bar 2.Select a product and click "Add to Cart" 3.Navigate to another product category 4.Select a different product and click "Add to Cart" 5.Repeat the process for multiple products 6.Navigate to the shopping cart page | H326: Category: Phones & PDAs | Product: HTC Touch HD Category: Desktops | Product: iPod Classic Category: Desktops | Product: Palm Treo Pro | I326: All selected products should be added successfully to the cart with correct product details, quantities, and prices displayed | J326: Multiple different products are added successfully to the cart | K326: Pass | L326: Critical | M326: Maryam Saleh | N326: 12/04/2026 | O326: —
...

Sheet 🔗 Traceability Matrix
A1: 🔗 Traceability Matrix — User Stories ↔ Test Scenarios ↔ Test Cases
A2: User Story ID | B2: User Story Title | C2: Acceptance Criteria | D2: Category | E2: Test Scenario ID | F2: Test Scenario Title | G2: TC Count | H2: Test Case IDs | I2: Coverage
A3: OC-REG-US-001 | B3: Successful Account Registration | C3: AC-01, AC-02 | D3: Functional | E3: TS-SUCC-001 | F3: Successful Account Registration | G3: 2 | H3: OC_AUTH_TC_001 OC_AUTH_TC_007 | I3: =IF(G3>0,"✅ 100%","❌ 0%") -> ✅ 100%
A4: OC-REG-US-002 | B4: First Name & Last Name Validation | C4: AC-01 to AC-05 | D4: Validation | E4: TS-NAME-001 | F4: Invalid First & Last Name | G4: 10 | H4: OC_AUTH_TC_014 OC_AUTH_TC_015 OC_AUTH_TC_021 OC_AUTH_TC_022 OC_AUTH_TC_023 OC_AUTH_TC_024 OC_AUTH_TC_025 OC_AUTH_TC_026 OC_AUTH_TC_037 OC_AUTH_TC_038 | I4: =IF(G4>0,"✅ 100%","❌ 0%") -> ✅ 100%
A5: OC-REG-US-002 | B5: First Name & Last Name Validation | C5: AC-05 | D5: Validation | E5: TS-NAME-002 | F5: First & Last Name Length Boundaries | G5: 10 | H5: OC_AUTH_TC_062 OC_AUTH_TC_070 OC_AUTH_TC_071 OC_AUTH_TC_072 OC_AUTH_TC_073 OC_AUTH_TC_063 OC_AUTH_TC_074 OC_AUTH_TC_075 OC_AUTH_TC_076 OC_AUTH_TC_077 | I5: =IF(G5>0,"✅ 100%","❌ 0%") -> ✅ 100%
A6: OC-REG-US-003 | B6: E-Mail Validation | C6: AC-01 to AC-06 | D6: Validation | E6: TS-EMAIL-001 | F6: Invalid Email Formats | G6: 10 | H6: OC_AUTH_TC_016 OC_AUTH_TC_027 OC_AUTH_TC_028 OC_AUTH_TC_029 OC_AUTH_TC_030 OC_AUTH_TC_031 OC_AUTH_TC_032 OC_AUTH_TC_008 OC_AUTH_TC_009 OC_AUTH_TC_039 | I6: =IF(G6>0,"✅ 100%","❌ 0%") -> ✅ 100%
A7: OC-REG-US-003 | B7: E-Mail Validation | C7: AC-05 | D7: Validation | E7: TS-EMAIL-002 | F7: Email Field Length Boundaries | G7: 6 | H7: OC_AUTH_TC_064 OC_AUTH_TC_065 OC_AUTH_TC_078 OC_AUTH_TC_079 OC_AUTH_TC_080 OC_AUTH_TC_081 | I7: =IF(G7>0,"✅ 100%","❌ 0%") -> ✅ 100%
A8: OC-REG-US-004 | B8: Telephone Validation | C8: AC-01 to AC-05 | D8: Validation | E8: TS-TEL-001 | F8: Invalid Telephone | G8: 5 | H8: OC_AUTH_TC_017 OC_AUTH_TC_033 OC_AUTH_TC_034 OC_AUTH_TC_035 OC_AUTH_TC_040 | I8: =IF(G8>0,"✅ 100%","❌ 0%") -> ✅ 100%
A9: OC-REG-US-004 | B9: Telephone Validation | C9: AC-04 | D9: Validation | E9: TS-TEL-002 | F9: Telephone Field Length Boundaries | G9: 6 | H9: OC_AUTH_TC_066 OC_AUTH_TC_067 OC_AUTH_TC_082 OC_AUTH_TC_083 OC_AUTH_TC_084 OC_AUTH_TC_085 | I9: =IF(G9>0,"✅ 100%","❌ 0%") -> ✅ 100%
A10: OC-REG-US-004 | B10: Telephone Validation | C10: AC-05 | D10: Validation | E10: TS-TEL-003 | F10: Duplicate Telephone | G10: 1 | H10: OC_AUTH_TC_010 | I10: =IF(G10>0,"✅ 100%","❌ 0%") -> ✅ 100%
A11: OC-REG-US-005 | B11: Password & Confirm Validation | C11: AC-01 to AC-06 | D11: Validation/Security | E11: TS-PASS-001 | F11: Password & Confirm Password Validation | G11: 6 | H11: OC_AUTH_TC_011 OC_AUTH_TC_018 OC_AUTH_TC_019 OC_AUTH_TC_020 OC_AUTH_TC_036 OC_AUTH_TC_041 | I11: =IF(G11>0,"✅ 100%","❌ 0%") -> ✅ 100%
A12: OC-REG-US-005 | B12: Password & Confirm Validation | C12: AC-06 | D12: Validation | E12: TS-PASS-002 | F12: Password Field Length Boundaries | G12: 6 | H12: OC_AUTH_TC_068 OC_AUTH_TC_069 OC_AUTH_TC_086 OC_AUTH_TC_087 OC_AUTH_TC_088 OC_AUTH_TC_089 | I12: =IF(G12>0,"✅ 100%","❌ 0%") -> ✅ 100%
A13: OC-REG-US-006 | B13: Newsletter Subscription | C13: AC-01 to AC-04 | D13: Functional | E13: TS-NEWS-001 to TS-NEWS-004 | F13: Newsletter Scenarios | G13: 4 | H13: OC_AUTH_TC_091 OC_AUTH_TC_092 OC_AUTH_TC_093 OC_AUTH_TC_094 | I13: =IF(G13>0,"✅ 100%","❌ 0%") -> ✅ 100%
A14: OC-REG-US-007 | B14: Privacy Policy Acceptance | C14: AC-01, AC-02 | D14: Functional | E14: TS-PP-001 | F14: Privacy Policy Validation | G14: 2 | H14: OC_AUTH_TC_012 OC_AUTH_TC_013 | I14: =IF(G14>0,"✅ 100%","❌ 0%") -> ✅ 100%
... A27: OC-LOG-US-009 | B27: Responsive Design & Browser Compatibility | C27: AC-01 to AC-03 | D27: Compatibility | E27: TS-COMP-009 | F27: Login Page Fully Responsive | G27: 3 | H27: OC_AUTH_TC_120 OC_AUTH_TC_121 OC_AUTH_TC_122 | I27: =IF(G27>0,"✅ 100%","❌ 0%") -> ✅ 100%

Sheet 🐞 Bug Log
A1: 🐞 OpenCart Platform — Bug / Defect Log
A2: Bug ID | B2: TC ID | C2: Linked User Story | D2: Bug Title | E2: Severity | F2: Priority | G2: Status | H2: Environment | I2: Steps to Reproduce | J2: Expected vs Actual | K2: Reported By | L2: Date Reported | M2: Attachments
A3: OC_AUTH_BUG_001 | B3: OC_AUTH_TC_002 | C3: OC-REG-US-009 / AC-01 | D3: On the Registration page | Entering a SQL injection payload in the First Name field and clicking Continue completes registration successfully | E3: Critical | F3: P0 | G3: Open | H3: Testing | OpenCart v3.x | Chrome 124 | Windows 10 | I3: 1. Navigate to Registration page 2. Enter SQL injection in First Name: ' OR '1'='1 3. Fill other fields with valid data 4. Accept Privacy Policy 5. Click Continue | J3: Expected: Registration rejected | No SQL error exposed | Generic validation message shown | Application remains stable Actual: System allowed registration | Account created with injected input stored in profile | No validation or sanitization applied | K3: Mohamed Ahmed | L3: 12/04/2026 | M3: Video: OC_AUTH_BUG_001.mp4 (in Bug_Evidences.zip)
A4: OC_AUTH_BUG_002 | B4: OC_AUTH_TC_010 | C4: OC-REG-US-004 / AC-05 | D4: On the Registration page | Entering a duplicate Telephone number and clicking Continue completes registration successfully | E4: Major | F4: P1 | G4: Open | H4: Testing | OpenCart v3.x | Chrome 124 | Windows 10 | I4: 1. Ensure Telephone: 0501234567 is already registered 2. Navigate to Registration page 3. Enter Telephone: 0501234567 (already registered) 4. Fill other fields with unique valid data 5. Accept Privacy Policy 6. Click Continue | J4: Expected: Registration rejected | Warning: Telephone is already registered Actual: Registration succeeded | Duplicate telephone allowed | Second account created with same phone number | K4: Mohamed Ahmed | L4: 12/04/2026 | M4: Video: OC_AUTH_BUG_002.mp4 (in Bug_Evidences.zip)
A5: OC_AUTH_BUG_003 | B5: OC_AUTH_TC_021 | C5: OC-REG-US-002 / AC-03 | D5: On the Registration page | Entering numeric characters in the First Name field and clicking Continue completes registration successfully | E5: Major | F5: P1 | G5: Open | H5: Testing | OpenCart v3.x | Chrome 124 | Windows 10 | I5: 1. Navigate to Registration page 2. Enter First Name: Mohamed123 3. Fill other fields with valid data 4. Accept Privacy Policy 5. Click Continue | J5: Expected: Registration rejected | Validation error: First Name should contain letters only Actual: Registration succeeded | Account created with numeric characters in First Name | No validation error shown | K5: Mohamed Ahmed | L5: 12/04/2026 | M5: Video: OC_AUTH_BUG_003.mp4 (in Bug_Evidences.zip)
A6: OC_AUTH_BUG_004 | B6: OC_AUTH_TC_022 | C6: OC-REG-US-002 / AC-03 | D6: On the Registration page | Entering special characters in the First Name field and clicking Continue completes registration successfully | E6: Major | F6: P1 | G6: Open | H6: Testing | OpenCart v3.x | Chrome 124 | Windows 10 | I6: 1. Navigate to Registration page 2. Enter First Name: Mohamed@#$ 3. Fill other fields with valid data 4. Accept Privacy Policy 5. Click Continue | J6: Expected: Registration rejected | Validation error displayed for First Name Actual: Registration succeeded | Account created with special characters stored in First Name | No validation error shown | K6: Mohamed Ahmed | L6: 12/04/2026 | M6: Video: OC_AUTH_BUG_004.mp4 (in Bug_Evidences.zip)
A7: OC_AUTH_BUG_005 | B7: OC_AUTH_TC_024 | C7: OC-REG-US-002 / AC-03 | D7: On the Registration page | Entering numeric characters in the Last Name field and clicking Continue completes registration successfully | E7: Major | F7: P1 | G7: Open | H7: Testing | OpenCart v3.x | Chrome 124 | Windows 10 | I7: 1. Navigate to Registration page 2. Enter Last Name: Smith123 3. Fill other fields with valid data 4. Accept Privacy Policy 5. Click Continue | J7: Expected: Registration rejected | Validation error for Last Name Actual: Registration succeeded | Account created with numeric characters in Last Name | No validation error shown | K7: Mohamed Ahmed | L7: 12/04/2026 | M7: Video: OC_AUTH_BUG_005.Png (in Bug_Evidences.zip)
A8: OC_AUTH_BUG_006 | B8: OC_AUTH_TC_025 | C8: OC-REG-US-002 / AC-03 | D8: On the Registration page | Entering special characters in the Last Name field and clicking Continue completes registration successfully | E8: Major | F8: P1 | G8: Open | H8: Testing | OpenCart v3.x | Chrome 124 | Windows 10 | I8: 1. Navigate to Registration page 2. Enter Last Name: Smith@#$ 3. Fill other fields with valid data 4. Accept Privacy Policy 5. Click Continue | J8: Expected: Registration rejected | Validation error displayed for Last Name Actual: Registration succeeded | Account created with special characters stored in Last Name | No validation error shown | K8: Mohamed Ahmed | L8: 12/04/2026 | M8: Video: OC_AUTH_BUG_006.Png (in Bug_Evidences.zip)
A9: OC_AUTH_BUG_007 | B9: OC_AUTH_TC_032 | C9: OC-REG-US-003 / AC-03 | D9: On the Registration page | Entering illegal characters in the Email field and clicking Continue completes registration successfully | E9: Major | F9: P1 | G9: Open | H9: Testing | OpenCart v3.x | Chrome 124 | Windows 10 | I9: 1. Navigate to Registration page 2. Enter Email: te#st@domain.com 3. Fill other fields with valid data 4. Accept Privacy Policy 5. Click Continue | J9: Expected: Registration rejected | Error: "E-Mail Address does not appear to be valid!" Actual: Registration succeeded | Account created with invalid email format containing illegal characters | K9: Mohamed Ahmed | L9: 12/04/2026 | M9: Video: OC_AUTH_BUG_007.Png (in Bug_Evidences.zip)
A10: OC_AUTH_BUG_008 | B10: OC_AUTH_TC_033 | C10: OC-REG-US-004 / AC-03 | D10: On the Registration page | Entering alphabetic characters in the Telephone field and clicking Continue completes registration successfully | E10: Major | F10: P1 | G10: Open | H10: Testing | OpenCart v3.x | Chrome 124 | Windows 10 | I10: 1. Navigate to Registration page 2. Enter Telephone: test (alphabetic) 3. Fill other fields with valid data 4. Accept Privacy Policy 5. Click Continue | J10: Expected: Registration rejected | Telephone must be numeric only Actual: Registration succeeded | Account created with alphabetic telephone value | No validation error shown | K10: Mohamed Ahmed | L10: 12/04/2026 | M10: Video: OC_AUTH_BUG_008.Png (in Bug_Evidences.zip)
A11: OC_AUTH_BUG_009 | B11: OC_AUTH_TC_034 | C11: OC-REG-US-004 / AC-03 | D11: On the Registration page | Entering special characters in the Telephone field and clicking Continue completes registration successfully | E11: Major | F11: P1 | G11: Open | H11: Testing | OpenCart v3.x | Chrome 124 | Windows 10 | I11: 1. Navigate to Registration page 2. Enter Telephone: te#st 3. Fill other fields with valid data 4. Accept Privacy Policy 5. Click Continue | J11: Expected: Registration rejected | Special characters in telephone not allowed Actual: Registration succeeded | Account created with special characters in telephone | No validation error shown | K11: Mohamed Ahmed | L11: 12/04/2026 | M11: Video: OC_AUTH_BUG_009.Png (in Bug_Evidences.zip)
A12: OC_AUTH_BUG_010 | B12: OC_AUTH_TC_035 | C12: OC-REG-US-004 / AC-03 | D12: On the Registration page | Entering whitespace-only input in the Telephone field and clicking Continue completes registration successfully | E12: Major | F12: P1 | G12: Open | H12: Testing | OpenCart v3.x | Chrome 124 | Windows 10 | I12: 1. Navigate to Registration page 2. Enter Telephone: " " (spaces only) 3. Fill other fields with valid data 4. Accept Privacy Policy 5. Click Continue | J12: Expected: Registration rejected | Whitespace-only telephone treated as empty | Validation error shown Actual: Registration succeeded | Account created with whitespace stored as telephone value | K12: Mohamed Ahmed | L12: 12/04/2026 | M12: Video: OC_AUTH_BUG_010.Png (in Bug_Evidences.zip)
A13: OC_AUTH_BUG_011 | B13: OC_AUTH_TC_036 | C13: OC-REG-US-005 / AC-05 | D13: On the Registration page | Entering whitespace-only input in the Password field and clicking Continue completes registration successfully | E13: Major | F13: P1 | G13: Open | H13: Testing | OpenCart v3.x | Chrome 124 | Windows 10 | I13: 1. Navigate to Registration page 2. Enter Password: " " (spaces only) 3. Enter Confirm Password: " " (spaces only) 4. Fill other fields with valid data 5. Accept Privacy Policy 6. Click Continue | J13: Expected: Registration rejected | Error: "Password must be between 4 and 20 characters!" Actual: Registration succeeded | Account created with whitespace-only password | Security risk | K13: Mohamed Ahmed | L13: 12/04/2026 | M13: Video: OC_AUTH_BUG_011.Png (in Bug_Evidences.zip)
... A17: OC_AUTH_BUG_015 | B17: OC_AUTH_TC_041 | C17: OC-REG-US-005 / AC-05 | D17: On the Registration page | Entering leading or trailing spaces in the Password field and clicking Continue completes registration successfully | E17: Minor | F17: P1 | G17: Open | H17: Testing | OpenCart v3.x | Chrome 124 | Windows 10 | I17: 1. Navigate to Registration page 2. Enter Password: " Test@123" (leading space) 3. Enter matching Confirm Password with same leading space 4. Fill other fields with valid data 5. Accept Privacy Policy 6. Click Continue | J17: Expected: Registration rejected or spaces trimmed from password Actual: Registration succeeded | Password stored with leading/trailing spaces | User may have difficulty logging in later | K17: Mohamed Ahmed | L17: 12/04/2026 | M17: Video: OC_AUTH_BUG_015.Png (in Bug_Evidences.zip)
A18: OC_AUTH_BUG_016 | B18: OC_AUTH_TC_052 | C18: OC-LOG-US-002 | D18: Login Fails When Email Contains Leading Spaces — Input Not Trimmed | E18: Major | F18: P1 | G18: Open | H18: Testing | OpenCart v3.x | Chrome 124 | Windows 10 | I18: 1. Navigate to login page 2. Enter email with leading space: " test@domain.com" 3. Enter valid password: Test123! 4. Click Login | J18: Expected: Leading spaces trimmed automatically, login succeeds Actual: Login failed — leading spaces not trimmed, validation error displayed | K18: Mohamed Ahmed | L18: 46124 | M18: Video: OC_AUTH_BUG_019.Png (in Bug_Evidences.zip)
A19: OC_AUTH_BUG_017 | B19: OC_AUTH_TC_057 | C19: OC-LOG-US-004 | D19: Password Reset Email Not Sent For Valid Registered Email | E19: Critical | F19: P1 | G19: Open | H19: Testing | OpenCart v3.x | Chrome 124 | Windows 10 | I19: 1. Navigate to Forgotten Password page 2. Enter registered email: test@domain.com 3. Click Continue 4. Check inbox for reset email | J19: Expected: Reset email received within a reasonable timeframe Actual: No reset email received — password reset process not completed. Blocks TC_019, TC_020, TC_026, TC_027 | K19: Mohamed Ahmed | L19: 46124 | M19: Video: OC_AUTH_BUG_020.Png (in Bug_Evidences.zip)
A20: OC_AUTH_BUG_018 | B20: OC_AUTH_TC_060 | C20: OC-LOG-US-005 | D20: Session Not Invalidated After Logout — Account Pages Accessible Via Browser Back Button | E20: Critical | F20: P1 | G20: Open | H20: Testing | OpenCart v3.x | Chrome 124 | Windows 10 | I20: 1. Log in with valid credentials 2. Navigate to My Account page 3. Click Logout 4. Press browser Back button 5. Observe if account page is accessible | J20: Expected: Account pages inaccessible after logout — redirected to login page Actual: Previously visited account page displayed again without re-authentication — session not invalidated | K20: Mohamed Ahmed | L20: 46124 | M20: Video: OC_AUTH_BUG_021.Png (in Bug_Evidences.zip)
A21: OC_AUTH_BUG_019 | B21: OC_AUTH_TC_064 | C21: OC-REG-US-003 / AC-05 | D21: On the Registration page | Entering an email below the minimum length (5 chars) and clicking Continue completes registration successfully | E21: Major | F21: P2 | G21: Open | H21: Testing | OpenCart v3.x | Chrome 124 | Windows 10 | I21: 1. Navigate to Registration page 2. Enter Email: a@b.c (5 chars, Min-1) 3. Fill other fields with valid data 4. Accept Privacy Policy 5. Click Continue | J21: Expected: Registration rejected | Error: "E-Mail Address does not appear to be valid!" Actual: Registration succeeded | Account created with email below minimum length | No error shown | K21: Mohamed Ahmed | L21: 12/04/2026 | M21: Video: OC_AUTH_BUG_016.Png (in Bug_Evidences.zip)
A22: OC_AUTH_BUG_020 | B22: OC_AUTH_TC_069 | C22: OC-REG-US-005 / AC-06 | D22: On the Registration page | Entering a password exceeding the maximum length (21+ chars) and clicking Continue completes registration successfully | E22: Major | F22: P2 | G22: Open | H22: Testing | OpenCart v3.x | Chrome 124 | Windows 10 | I22: 1. Navigate to Registration page 2. Enter Password: 21-character string (Max+1) 3. Enter matching Confirm Password 4. Fill other fields with valid data 5. Accept Privacy Policy 6. Click Continue | J22: Expected: Registration rejected | Error: "Password must be between 4 and 20 characters!" Actual: Registration succeeded | Account created with over-length password | No validation error shown | K22: Mohamed Ahmed | L22: 12/04/2026 | M22: Video: OC_AUTH_BUG_017.Png (in Bug_Evidences.zip)
A23: OC_AUTH_BUG_021 | B23: OC_AUTH_TC_099 | C23: OC-LOG-US-004 | D23: Password Reset Email Not Delivered On Resend Attempt | E23: Minor | F23: P2 | G23: Open | H23: Testing | OpenCart v3.x | Chrome 124 | Windows 10 | I23: 1. Navigate to Forgotten Password page 2. Enter registered email and click Continue 3. Return to Forgotten Password page 4. Re-enter same email and click Continue 5. Check inbox for new reset email | J23: Expected: New reset email sent successfully — user can request multiple times Actual: No reset email delivered on retry — resend functionality not working | K23: Mohamed Ahmed | L23: 46124 | M23: Video: OC_AUTH_BUG_022.Png (in Bug_Evidences.zip)
A24: OC_AUTH_BUG_022 | B24: OC_AUTH_TC_109 | C24: OC-REG-US-010 / AC-02 | D24: On the Registration page | The Password field displays the browser-native visibility toggle instead of the custom one when opened in Chrome | E24: Low | F24: P3 | G24: Open | H24: Testing | OpenCart v3.x | Chrome 124 | Windows 10 | I24: 1. Navigate to Registration page 2. Locate Password field in Chrome browser 3. Observe whether a custom password visibility toggle is present 4. Click toggle if visible to verify show/hide functionality | J24: Expected: Custom visibility toggle visible next to Password field | Toggle works correctly in Chrome Actual: Password visibility toggle is not displayed in Chrome | Toggle control missing | Users cannot enable/disable password visibility in Chrome | K24: Mohamed Ahmed | L24: 12/04/2026 | M24: Video: OC_AUTH_BUG_018.Png (in Bug_Evidences.zip)
A25: OC_AUTH_BUG_023 | B25: OC_AUTH_TC_116 | C25: OC-LOG-US-008 | D25: Password Visibility Toggle Not Displayed In Chrome Browser | E25: Low | F25: P3 | G25: Open | H25: Testing | OpenCart v3.x | Chrome 124 | Windows 10 | I25: 1. Open login page in Chrome 2. Locate password field 3. Look for visibility toggle icon 4. Repeat in Edge for comparison | J25: Expected: Custom visibility toggle visible in both Chrome and Edge — toggles password show/hide Actual: Toggle missing in Chrome — feature unavailable. Works correctly in Edge only | K25: Mohamed Ahmed | L25: 46124 | M25: Video: OC_AUTH_BUG_023.Png (in Bug_Evidences.zip)
A26: OC_SEAR_BUG_001 | B26: OC_SEAR_TC_136 | C26: — | D26: Shopping cart count updates in header | E26: Minor | F26: P2 | G26: Open | H26: Testing | OpenCart v3.x | Chrome 124 | Windows 10 | I26: 1. Note cart count in header 2. Add an item to cart 3. Return to search page | J26: Expected: Cart count and total update dynamically in header. Actual: No cart count is displayed the website doesn't show the number of cart items beside the cart icon | K26: Mohamed Ashraf | L26: 12/04/2026 | M26: Video: OC_SEAR_BUG_001.mp4 (in Bug_Evidences.zip)
A27: OC_SEAR_BUG_002 | B27: OC_SEAR_TC_137 | C27: — | D27: Autocomplete behavior in keyword field | E27: Minor | F27: P2 | G27: Open | H27: Testing | OpenCart v3.x | Chrome 124 | Windows 10 | I27: 1. Start typing 'iPh' 2. Pause 1-2 seconds 3. Observe if suggestions appear | J27: Expected: Autocomplete suggestions appear. Actual: No Autocomplete suggestions appear. | K27: Mohamed Ashraf | L27: 12/04/2026 | M27: Video: OC_SEAR_BUG_002.mp4 (in Bug_Evidences.zip)
A28: OC_SEAR_BUG_003 | B28: OC_SEAR_TC_140 | C28: — | D28: BVA - Exceeding max: 256+ characters | E28: Minor | F28: P2 | G28: Open | H28: Testing | OpenCart v3.x | Chrome 124 | Windows 10 | I28: 1. Paste 500-character string 2. Click Search | J28: Expected: Input truncated to max length OR validation error shown. No server error. Actual: Input accepted and processed without truncation or error. | K28: Mohamed Ashraf | L28: 12/04/2026 | M28: Video: OC_SEAR_BUG_003.mp4 (in Bug_Evidences.zip)
A29: OC_SEAR_BUG_004 | B29: OC_SEAR_TC_146 | C29: — | D29: EP - Multi-word keyword | E29: Minor | F29: P2 | G29: Open | H29: Testing | OpenCart v3.x | Chrome 124 | Windows 10 | I29: 1. Enter 'Apple MacBook Pro' 2. Click Search | J29: Expected: Products matching all or part of multi-word query returned. Actual: The search doesn't return any results | K29: Mohamed Ashraf | L29: 12/04/2026 | M29: Video: OC_SEAR_BUG_004.mp4 (in Bug_Evidences.zip)
A30: OC_SEAR_BUG_005 | B30: OC_SEAR_TC_147 | C30: — | D30: Search with whitespace-only input | E30: Minor | F30: P2 | G30: Open | H30: Testing | OpenCart v3.x | Chrome 124 | Windows 10 | I30: 1. Enter only spaces in Keywords 2. Click Search | J30: Expected: System trims to empty and returns empty results. Actual: The search returns all available products on the website | K30: Mohamed Ashraf | L30: 12/04/2026 | M30: Video: OC_SEAR_BUG_005.mp4 (in Bug_Evidences.zip)
A31: OC_CAT_BUG_001 | B31: OC_CAT_TC_166 | C31: — | D31: Click 'Desktops' category as logged-in user | E31: Major | F31: P1 | G31: Open | H31: Testing | OpenCart v3.x | Chrome 124 | Windows 10 | I31: 1. Log in 2. Click 'Desktops' from navigation bar 3. Click on show all Desktops | J31: Expected: User is redirected to Desktops category page. Desktops products are listed. Actual: User is redirected to Desktops but wrong product items are listed | K31: Mohamed Ashraf | L31: 12/04/2026 | M31: Video: OC_CAT_BUG_001.mp4 (in Bug_Evidences.zip)
A32: OC_CAT_BUG_002 | B32: OC_CAT_TC_168 | C32: — | D32: Click 'Components' category as logged-in user | E32: Major | F32: P1 | G32: Open | H32: Testing | OpenCart v3.x | Chrome 124 | Windows 10 | I32: 1. Log in 2. Click 'Components' from navigation bar 3. Click on show all Components | J32: Expected: Components category page loads with relevant products or subcategories. Actual: Components category page loads with empty product list. | K32: Mohamed Ashraf | L32: 12/04/2026 | M32: Video: OC_CAT_BUG_002.mp4 (in Bug_Evidences.zip)
A33: OC_CAT_BUG_003 | B33: OC_CAT_TC_177 | C33: — | D33: Featured products on Hero banner link to correct product pages | E33: Major | F33: P1 | G33: Open | H33: Testing | OpenCart v3.x | Chrome 124 | Windows 10 | I33: 1. On homepage, browse the Hero banner products with left and right arrows 2. Click on McBook image | J33: Expected: User is directed to McBook products page. Actual: Clicking on McBook image does not redirect the user to the associated product page; the page remains static | K33: Mohamed Ashraf | L33: 12/04/2026 | M33: Video: OC_CAT_BUG_003.mp4 (in Bug_Evidences.zip)
A34: OC_CAT_BUG_004 | B34: OC_CAT_TC_178 | C34: — | D34: Featured products on Hero banner link to correct product pages (iPhone) | E34: Major | F34: P1 | G34: Open | H34: Testing | OpenCart v3.x | Chrome 124 | Windows 10 | I34: 1. On homepage, browse the Hero banner products with left and right arrows 2. Click on iPhone image | J34: Expected: User is directed to iPhone products page. Actual: User is directed to Samsung Galaxy Tab 10.1 product details page. | K34: Mohamed Ashraf | L34: 12/04/2026 | M34: Video: OC_CAT_BUG_004.mp4 (in Bug_Evidences.zip)
A35: OC_CAT_BUG_005 | B35: OC_CAT_TC_191 | C35: — | D35: Keyboard navigation through category links | E35: Low | F35: P3 | G35: Open | H35: Testing | OpenCart v3.x | Chrome 124 | Windows 10 | I35: 1. Log in 2. Tab to the navigation bar 3. Use Tab to move through categories 4. Press Enter on 'Tablets' | J35: Expected: Focus moves through each nav link. Pressing Enter navigates to the correct category. Actual: Focus moves through each nav link except categories that have subcategories under them (Desktops, Laptops & Notebooks, Components, MP3 Players). Pressing Enter navigates to the correct category. | K35: Mohamed Ashraf | L35: 12/04/2026 | M35: Video: OC_CAT_BUG_005.mp4 (in Bug_Evidences.zip)
A36: OC_WISHLIST_BUG_001 | B36: OC_WISHLIST_TC_268 | C36: — | D36: Verify Wishlist access behavior after login with active session and login prompt inconsistency | E36: Major | F36: P1 | G36: Open | H36: Testing | OpenCart v3.x | Chrome 124 | Windows 10 | I36: 1. Open the website 2. Login with valid credentials 3. Navigate to Wishlist page 4. Verify Wishlist is displayed correctly for logged-in user 5. Logout from the application 6. Try to access Wishlist page directly via URL or navigation 7. Observe system behavior 8. Verify redirection to Login page for logged-out user 9. Check if any login popup/message appears inconsistently during navigation | J36: Expected: Wishlist should be accessible only for authenticated users Logged-in user can access Wishlist without any issue Logged-out user should be redirected to Login page when accessing Wishlist No inconsistent or repeated login prompts should appear System should handle session properly without access bypass or UI issues Actual: User remains on the Wishlist page after clicking Logout from the sidebar. A "Continue" button is displayed, along with a message indicating that data is saved and that the saved Wishlist items will be available after logging in again. When the user clicks the "Continue" button, they are redirected to the Home Page instead of being prompted to log in again. | K36: Mariam Elgandour | L36: 12/04/2026 | M36: Video: OC_WISHLIST_BUG_001.mp4 (in Bug_Evidences.zip)
A37: OC_WISHLIST_BUG_002 | B37: OC_WISHLIST_TC_270 | C37: — | D37: Verify feedback message when adding an already existing product to Wishlist | E37: Minor | F37: P3 | G37: Open | H37: Testing | OpenCart v3.x | Chrome 124 | Windows 10 | I37: 1. Open the website 2. Navigate to the product list page 3. Add a product to Wishlist using the heart icon 4. Verify the product is added in Wishlist 5. Return to the same product again 6. Click on the heart icon for the same product 7. Observe the system feedback/message 8. Verify whether the system prevents duplicate addition or not | J37: Expected: The system should prevent duplicate product addition OR show a proper message The user should receive a clear feedback message (e.g., already in Wishlist) The product should not be duplicated in the Wishlist Wishlist should maintain unique items only No UI or functional issues should occur Actual: When adding a product that already exists in the Wishlist, the system does not duplicate the product. However, it displays a success notification message indicating that the product has been added again, which is misleading to the user. | K37: Mariam Elgandour | L37: 12/04/2026 | M37: Video: OC_WISHLIST_BUG_002.mp4 (in Bug_Evidences.zip)
